<?xml version="1.0"?>
<robot name="simple_bot">
  <link name="base_link">
    <visual>
      <geometry><box size="0.6 0.4 0.2"/></geometry>
    </visual>
  </link>
  <link name="right_wheel_link">
    <visual>
      <geometry><cylinder radius="0.1" length="0.05"/></geometry>
    </visual>
  </link>
  <joint name="base_to_right_wheel" type="continuous">
    <parent link="base_link"/>
    <child link="right_wheel_link"/>
    <origin xyz="0 -0.25 0" rpy="1.5707 0 0"/>
    <axis xyz="0 0 1"/>
  </joint>
</robot>
